Workbook

Sheet Assumptions
A1: Transiberia — Business Case Assumptions
A2: Editable inputs (blue) drive every formula on the Calculations tab. Column D shows where every number comes from — client-stated, a numbered external benchmark (full citation at the bottom of this tab), or a SilverTrust planning assumption. Yellow = please confirm/complete with Marc.
A3: Input | B3: Value | C3: Unit | D3: Source / basis
A4: CURRENT OPERATIONS (client-stated, from the interview & proposal)
A5: Weekly loads | B5: 1000 | C5: loads/week | D5: Client — Transiberia interview
A6: Operating weeks per year | B6: 52 | C6: weeks | D6: Standard — calendar year
A7: Current employees | B7: 120 | C7: people | D7: Client — Transiberia interview
A8: Lost hours/week — low | B8: 20 | C8: hours | D8: Client — Transiberia interview (firefighting/reactive time)
A9: Lost hours/week — high | B9: 30 | C9: hours | D9: Client — Transiberia interview
A10: Current operational cost per load | B10: 80 | C10: €/load | D10: Client — Transiberia interview
A11: Target operational cost per load | B11: 40 | C11: €/load | D11: Client — stated target (€80 → €40/load)
A12: Current carrier assignment time | B12: 8 | C12: hours | D12: Client — stated current state
A13: Target carrier assignment time | B13: 2 | C13: hours | D13: Client — stated target (8h → 2h)
A15: LABOR COST — BARCELONA
A16: Gross annual salary — ops/admin role | B16: 29000 | C16: €/year | D16: External [1] Glassdoor — Logistics Coordinator, Barcelona (median)
A17: Employer social security rate (Spain) | B17: 0.3 | C17: % of salary | D17: External [2] Centre Gestor — Spain employer SS contributions
A18: Other overhead loading (equipment, IT, etc.) | B18: 0.05 | C18: % of salary | D18: SilverTrust assumption — illustrative, not independently sourced
A19: Loaded annual cost per employee | B19: =B16*(1+B17+B18) -> 39150 | C19: €/year | D19: Calculated — see formula
A20: Standard working week | B20: 40 | C20: hours/week | D20: External [3] Rivermate — Spain working hours
A21: Statutory annual leave | B21: 22 | C21: working days | D21: External [4] Boundless HQ — Spain statutory leave
A22: Public holidays | B22: 14 | C22: days/year | D22: External [4] Boundless HQ — Spain statutory leave
A23: Hours per working day | B23: 8 | C23: hours/day | D23: Standard — full-time definition
A24: Effective working hours per year | B24: =(B20*B6)-(B21*B23)-(B22*B23) -> 1792 | C24: hours | D24: Calculated — see formula
A25: Loaded hourly rate | B25: =B19/B24 -> 21.847098 | C25: €/hour | D25: Calculated — see formula
A27: EXCEPTIONS & RISK
A28: Exception rate — low | B28: 0.03 | C28: % of loads | D28: Client — Transiberia interview (3–5% delays/missing shipments)
A29: Exception rate — high | B29: 0.05 | C29: % of loads | D29: Client — Transiberia interview
A30: Fatal / catastrophic incidents (max) | B30: 5 | C30: per month | D30: Client — Transiberia interview
A31: Fatal incident cap | B31: 50000 | C31: €/incident | D31: Client — Transiberia interview
A32: Assumed avg. severity vs. cap | B32: 0.2 | C32: % of cap | D32: SilverTrust assumption — illustrative, not independently sourced
A34: MARGIN & GROWTH TARGET
A35: Current margin — low | B35: 0.05 | C35: % per pallet | D35: Client — Transiberia interview (5–6% margin per pallet)
A36: Current margin — high | B36: 0.06 | C36: % per pallet | D36: Client — Transiberia interview
A37: Current annual revenue (ESTIMATED, not confirmed) | B37: ='Revenue Estimate'!B20 -> 53213333 | C37: €/year | D37: Estimated — see Revenue Estimate tab for method & sources
A38: Target volume — low (+25%) | B38: 1250 | C38: loads/week | D38: Client — stated growth target (+25% volume)
A39: Target volume — high (+50%) | B39: 1500 | C39: loads/week | D39: SilverTrust assumption — upside scenario, not client-stated
A40: Target revenue growth — low | B40: 0.3 | C40: % | D40: Client — stated growth target (30–40% revenue)
A41: Target revenue growth — high | B41: 0.4 | C41: % | D41: Client — stated growth target
A43: INVESTMENT & SYSTEM COSTS (n8n on-premise AI build — SilverTrust boutique tier, Sep 2026)
A44: Core build investment — consulting only, before contingency | B44: 40400 | C44: € | D44: SilverTrust — Consultancy Build Cost doc, boutique tier (see 'SilverTrust Cost Detail' tab)
...

Sheet SilverTrust Cost Detail
A1: SilverTrust Cost Detail — Day-Rate Card & Effort by Phase (Boutique Tier)
A2: Bottom-up build of SilverTrust's fee: SilverTrust's boutique-tier day rates (blue, Section A) applied to the estimated effort for each phase (days in blue, Sections B–E). Extended cost and phase subtotals are formulas — matches the task-by-task breakdown in the Consultancy Build Cost document. Section G benchmarks this against mid-market and Big 4 pricing for the same scope. This is SilverTrust's internal planning model — the commercial price quoted to Transiberia is the fixed figure on the proposal's 'Investment & Cost Estimate' slide (and the Assumptions tab); remove this tab before sharing the file externally if it isn't meant for the client.
A3: Item | B3: Rate / Days | C3: Days | D3: Extended Cost | E3: Notes / basis
A4: A — SILVERTRUST DAY-RATE CARD (BOUTIQUE / FREELANCE TIER)
A5: Sr Consultant | B5: 550 | C5: €/day | E5: SilverTrust standard day-rate card — illustrative, confirm current published rates before quoting
A6: Technical Lead | B6: 600 | C6: €/day | E6: SilverTrust standard day-rate card — illustrative, confirm current published rates before quoting
A7: Consultant | B7: 500 | C7: €/day | E7: SilverTrust standard day-rate card — illustrative, confirm current published rates before quoting
A8: AI Specialist | B8: 550 | C8: €/day | E8: SilverTrust's boutique/freelance tier: €400–600/day — Spain/Portugal/Eastern EU rates. Benchmarked against [5] YunoJuno 2025 Freelancer Rates Report, [6] goLance AI Consultant Rate Guide 2026, [7] EU SME AI Consulting Market 2026 (see Assumptions tab sources).
A10: B — PHASE 0: DISCOVERY & ASSESSMENT (Wks 1–4)
A11: Process audit | B11: =B5 -> 550 | C11: 5 | D11: =B11*C11 -> 2750 | E11: Map SAP email flow, WhatsApp workflow, exception handling. Interviews with ops team.
A12: Technical assessment | B12: =B6 -> 600 | C12: 4 | D12: =B12*C12 -> 2400 | E12: SAP email config, carrier WA volume, GPS selection, VPS sizing, data schema design.
A13: Architecture design | B13: =B5 -> 550 | C13: 3 | D13: =B13*C13 -> 1650 | E13: Final n8n workflow design, AI node spec, integration map, EU AI Act classification.
A14: Phase 0 total | D14: =SUM(D11:D13) -> 6800 | E14: Proposal line item: €6,800. Matches the proposal's cost table and Roadmap Phase 1 (Discovery & Assessment).
A16: C — PHASE 1: INFRASTRUCTURE & INTEGRATIONS (Wks 5–12)
A17: Server setup | B17: =B6 -> 600 | C17: 3 | D17: =B17*C17 -> 1800 | E17: Hetzner VPS, Docker Compose, n8n + PostgreSQL + Ollama, nginx + SSL, monitoring.
A18: SAP email integration | B18: =B6 -> 600 | C18: 3 | D18: =B18*C18 -> 1800 | E18: IMAP trigger, sender allowlist validation, template parser, error handling.
A19: WhatsApp API setup | B19: =B7 -> 500 | C19: 4 | D19: =B19*C19 -> 2000 | E19: Meta business verification, message templates, n8n WA node, inbound webhook config.
A20: GPS integration | B20: =B6 -> 600 | C20: 4 | D20: =B20*C20 -> 2400 | E20: Webfleet/Teltonika webhook config, position ingestion into PostgreSQL, geofence setup.
A21: HERE routing API | B21: =B7 -> 500 | C21: 3 | D21: =B21*C21 -> 1500 | E21: Route baseline calculation at load creation, ETA storage, deviation threshold config.
A22: Google Sheets dashboard | B22: =B7 -> 500 | C22: 2 | D22: =B22*C22 -> 1000 | E22: Live ops schema, n8n write nodes, column mapping, conditional formatting rules.
A23: Phase 1 total | D23: =SUM(D17:D22) -> 10500 | E23: Proposal line item: €10,500. Matches the proposal's cost table and Roadmap Phase 2 (Infrastructure & AI Nodes).
A25: D — PHASE 2: AI NODES (Wks 9–16, parallel)
A26: Doc extraction LLM | B26: =B8 -> 550 | C26: 6 | D26: =B26*C26 -> 3300 | E26: Prompt design, few-shot examples, field validation, output parsing. Tested on 200+ messages.
A27: Exception classifier | B27: =B8 -> 550 | C27: 5 | D27: =B27*C27 -> 2750 | E27: Classification taxonomy, prompt engineering, confidence scoring, escalation threshold tuning.
A28: Route deviation logic | B28: =B6 -> 600 | C28: 4 | D28: =B28*C28 -> 2400 | E28: GPS vs route baseline comparison, deviation thresholds (distance + time), alert trigger logic.
A29: Carrier scorer | B29: =B8 -> 550 | C29: 6 | D29: =B29*C29 -> 3300 | E29: PostgreSQL data model, SQL queries, Python ranking script (pandas + scikit-learn), n8n integration.
A30: Phase 2 total | D30: =SUM(D26:D29) -> 11750 | E30: Proposal line item: €11,750. Matches the proposal's cost table — built in parallel with Phase 1 from Wk 9, not a later add-on.
A32: E — PHASE 3: TESTING, PILOT & HANDOVER (Wks 17–20)
A33: End-to-end testing | B33: =B6 -> 600 | C33: 5 | D33: =B33*C33 -> 3000 | E33: Test all workflows with real loads. Fix edge cases. Stress test classifier and GPS deviation.
A34: Ops team training | B34: =B5 -> 550 | C34: 3 | D34: =B34*C34 -> 1650 | E34: Train dispatchers on Google Sheets dashboard, alert handling. Document standard operating procedures.
A35: Handover & documentation | B35: =B6 -> 600 | C35: 2 | D35: =B35*C35 -> 1200 | E35: Technical runbook, n8n workflow exports, Ollama config, maintenance guide for a client-side maintenance engineer.
A36: Project management | B36: =B5 -> 550 | C36: 10 | D36: =B36*C36 -> 5500 | E36: 20 weeks × 0.5 day/week PM overhead. Client comms, sprint planning, risk tracking.
A37: Phase 3 total | D37: =SUM(D33:D36) -> 11350 | E37: Proposal line item: €11,350. Matches the proposal's cost table. On the Roadmap slide this window is shown as three delivery stages (Testing & Pilot, Full Rollout & Training, Handover & Maintenance) — the underlying fee is unchanged.
A39: F — BUILD TOTAL & CONTINGENCY
A40: BUILD TOTAL — bottom-up (consulting only, before contingency) | D40: =D14+D23+D30+D37 -> 40400
A41: With 15% contingency | D41: =D40*1.15 -> 46460 | E41: Same 15% contingency shown on the proposal's cost table.
A42: Core build investment per proposal (Assumptions tab, before contingency) | D42: =Assumptions!B44 -> 40400
A43: Variance (bottom-up vs. Assumptions tab) | D43: =D40-D42 -> 0 | E43: Should be zero — both figures come from the same Consultancy Build Cost doc. A non-zero variance means one of the two was edited without the other.
A45: G — BENCHMARK: BUILD COST BY CONSULTANCY TIER (same 20-week scope)
A46: Reference only — mid-market and Big 4 phase rows below are typed from the Consultancy Build Cost doc's own tier tables (single blended role per phase, not task-level), not built up from SilverTrust's day-rate card.
...

Sheet n8n Running Costs
A1: n8n Running Costs — Client-Side, Per Integration
A2: Per-component setup and recurring cost for the self-hosted n8n architecture — from the SilverTrust n8n Cost Breakdown doc. Component figures below are for reference/traceability (some are single values, some ranges, some conditional on device count — not summed component-by-component). The TOTAL COST SUMMARY at the bottom uses the doc's own official totals as blue inputs, and is what links back to the Assumptions tab.
A3: Component | B3: What it is / notes | C3: Setup cost | D3: Monthly | E3: AI consultant can do it?
A4: n8n (self-hosted) on Linux VPS | B4: Hetzner CX32: 4 vCPU, 8GB RAM, 80GB SSD. Docker + nginx + SSL. Community Edition: unlimited workflows/executions, no licence fee. | C4: ~€150 (server setup) | D4: €12–20 (Hetzner VPS) | E4: YES
A5: PostgreSQL (same server) | B5: Historical loads, carrier scores, route baselines, exception log. Installed via Docker. No additional licence. | C5: Included in VPS setup | D5: €0 (same server) | E5: YES
A6: Ollama — local LLM (same server) | B6: Runs open-source models (Llama 3, Mistral, Qwen) locally. Free software. 7B model on 8GB RAM sufficient at this volume. No API cost. | C6: €0 software + config time | D6: €0 (electricity only) | E6: YES (with ML basics)
A7: WhatsApp Business API (Meta direct) | B7: Meta Cloud API — free access. Inbound & 24h-window replies free. Utility templates (ES/PT) ~€0.04–0.06/msg. ~500 outbound templates/week. | C7: ~€200 (Meta verification + setup) | D7: €80–120 (template messages) | E7: PARTIAL (Meta approval needed)
A8: Google Sheets API | B8: Live ops dashboard, one row per load. n8n native node. Included in Google Workspace Business Starter if already held. | C8: €0 (n8n native node) | D8: €0–6 (if Workspace not held) | E8: YES
A9: SAP email integration | B9: n8n IMAP/SMTP node reads emails from SAP-authorised sender; validates sender + template before processing. No SAP API or BTP needed — works with any SAP version that can send email. | C9: €0 (n8n IMAP node) | D9: €0 | E9: YES
A10: GPS — Webfleet (TomTom), recommended | B10: Best fit ES/PT. Carrier installs OBD device (~€80 one-off) or uses free Webfleet app. Webfleet API → n8n webhook every 5 min. 20–30 key vehicles. | C10: €80/device (OBD) or €0 (app) | D10: €300–500 (20–30 key vehicles) | E10: PARTIAL (API config yes; carrier onboarding: ops)
A11: GPS — Teltonika, alternative | B11: Cheaper hardware option (~€60–90/device). Open REST/MQTT API — no per-vehicle fee beyond SIM (~€3–5/mo/device). Better long-term cost control. Alternative to Webfleet, not additive. | C11: €60–90/device + SIM setup | D11: €60–150 (20–30 devices + SIM) | E11: PARTIAL (hardware install: ops)
A12: Route baseline (HERE Routing API) | B12: Pre-calculates expected route/distance/ETA per load at booking. 250,000 free requests/month; ~4,000 calcs/month at this volume — comfortably within free tier. | C12: €0 (free tier) | D12: €0 (free tier) | E12: YES
A13: AI — doc extraction (Ollama/LLM) | B13: Extracts carrier, load ref, origin, destination, weight, rate, ETA from PDF CMRs, rate confirmations, WhatsApp messages. Runs locally — zero ongoing cost. | C13: ~€600 (prompt design + testing) | D13: €0 (local LLM) | E13: YES (prompt eng. skill needed)
A14: AI — exception classifier (Ollama/LLM) | B14: Classifies each message/GPS deviation: on-track, likely late, confirmed late, missing, possible fraud, needs human review. n8n AI node → local Ollama. | C14: ~€500 (classifier design + test) | D14: €0 (local LLM) | E14: YES (AI consultant core skill)
... A16: Dispatcher alert interface | B16: Alerts via email (n8n native) and WhatsApp: load ref, AI classification, confidence score, recommended action, Sheets link. No separate app/dashboard. | C16: €0 (n8n email + WA node) | D16: €0 | E16: YES
A18: TOTAL COST SUMMARY (official, as stated in the n8n Cost Breakdown doc)
A19: Total one-time setup cost — low | C19: 3250 | D19: € | E19: n8n Cost Breakdown doc — Total Cost Summary
A20: Total one-time setup cost — high | C20: 4500 | D20: € | E20: n8n Cost Breakdown doc — Total Cost Summary
A21: Total monthly recurring — low | C21: 462 | D21: €/month | E21: n8n Cost Breakdown doc — Total Cost Summary
A22: Total monthly recurring — high | C22: 700 | D22: €/month | E22: n8n Cost Breakdown doc — Total Cost Summary
A23: Annual total, Year 1 (setup + 12 × monthly) — low | C23: =C19+C21*12 -> 8794 | D23: €/year
A24: Annual total, Year 1 (setup + 12 × monthly) — high | C24: =C20+C22*12 -> 12900 | D24: €/year
A26: COMPARISON — VS. SAP BTP ROUTE
A27: SAP BTP Integration Suite licence alone — low | C27: 20000 | D27: €/year | E27: n8n Cost Breakdown doc — comparison line
A28: SAP BTP Integration Suite licence alone — high | C28: 40000 | D28: €/year | E28: n8n Cost Breakdown doc — comparison line
A29: Saving vs. SAP BTP route — low | C29: 11000 | D29: €/year | E29: n8n Cost Breakdown doc — comparison line
A30: Saving vs. SAP BTP route — high | C30: 30000 | D30: €/year | E30: n8n Cost Breakdown doc — comparison line
A32: All figures on this tab are SilverTrust planning estimates from the n8n Cost Breakdown doc, pending final vendor quotes (Hetzner, Meta, Webfleet/Teltonika) — same caveat as the proposal's Sources & Caveats slide.

Sheet Revenue Estimate
A1: Revenue Estimate — Not Provided by Client
A2: Transiberia's interview gave margin % and admin cost, but no revenue figure. This tab triangulates an estimate from two independent methods so the business case isn't blocked on it — replace with the real number as soon as you have it.
A4: METHOD 1 — MARGIN-ANCHORED (Transiberia's own stated numbers)
A5: Total administrative cost (annual) | B5: =Assumptions!B10*Assumptions!B5*Assumptions!B6 -> 4160000 | D5: From Assumptions — €80/load × 1,000 loads/week × 52 weeks
A6: Assumed operating loss, as % of admin cost | B6: 0.15 | C6: %
A7: Implied gross margin (opex minus assumed loss) | B7: =B5*(1-B6) -> 3536000 | D7: What gross margin must be, if opex exceeds it by the assumed loss
A8: Implied revenue — at stated margin range | B8: =B7/Assumptions!B36 -> 58933333 | C8: =B7/Assumptions!B35 -> 70720000 | D8: Revenue = implied gross margin ÷ margin% (high margin% → lower revenue; low margin% → higher revenue)
A10: METHOD 2 — MARKET RATE CROSS-CHECK (Spain–Portugal road freight benchmark)
A11: Rate per loading metre (LDM) — low | B11: 82 | C11: €/LDM
A12: Rate per loading metre (LDM) — high | B12: 118 | C12: €/LDM
A13: Assumed loading metres per load | B13: 8 | C13: LDM
A14: Implied revenue per load | B14: =B11*B13 -> 656 | C14: =B12*B13 -> 944 | D14: Rate/LDM × assumed LDM/load
A15: Implied annual revenue | B15: =B14*Assumptions!B5*Assumptions!B6 -> 34112000 | C15: =C14*Assumptions!B5*Assumptions!B6 -> 49088000 | D15: × 1,000 loads/week × 52 weeks
A17: CONSOLIDATED ESTIMATE
A18: Low end | B18: =MIN(B8:C8,B15:C15) -> 34112000 | D18: Lowest figure across both methods
A19: High end | B19: =MAX(B8:C8,B15:C15) -> 70720000 | D19: Highest figure across both methods
A20: Central planning estimate (used on Assumptions tab) | B20: =AVERAGE(AVERAGE(B8:C8),AVERAGE(B15:C15)) -> 53213333 | D20: Simple average of each method's midpoint — a planning placeholder only.
A22: Sources
A23: [5] GoFreight — freight-forwarder gross margin benchmarks by service line | B23: gofreight.com/glossary/what-is-the-gross-margin-of-freight-forwarders.html
A24: [5] Trans-road — European Road Freight Rate Benchmark 2026 | B24: trans-road.com/en/freight-rates/europe-benchmark-2026
A25: Note: all other figures on this tab not listed above are SilverTrust planning assumptions, not independently sourced — see column D on each row.

Sheet Calculations
A1: Transiberia — Cost, Risk & Scaling Model
A2: All figures are formulas driven by the Assumptions tab — change an input there and everything here recalculates.
B4: Low / current | C4: High / target | D4: Notes
A5: 1 — COST OF LOST HOURS (20–30 hrs/week firefighting)
A6: Weekly cost | B6: =Assumptions!B25*Assumptions!B8 -> 436.94196 | C6: =Assumptions!B25*Assumptions!B9 -> 655.41295 | D6: Loaded hourly rate × lost hours
A7: Annual cost | B7: =B6*Assumptions!B6 -> 22720.982 | C7: =C6*Assumptions!B6 -> 34081.473 | D7: Already embedded inside the €/load processing cost below — not additive to Section 2.
A9: 2 — PROCESSING COST: CURRENT vs TARGET €/LOAD
A10: Annual cost at current €/load | B10: =Assumptions!B10*Assumptions!B5*Assumptions!B6 -> 4160000 | D10: €80/load × 1,000 loads/week × 52 weeks
A11: Annual cost at target €/load | B11: =Assumptions!B11*Assumptions!B5*Assumptions!B6 -> 2080000 | D11: €40/load target × same volume
A12: SAVINGS at current volume (headline) | B12: =B10-B11 -> 2080000 | D12: The primary, non-double-counted savings figure at today's volume.
A13: Carrier assignment cycle time | B13: =Assumptions!B12 -> 8 | C13: =Assumptions!B13 -> 2 | D13: Cycle-time KPI (mostly wait time) — driver of the desk-throughput gain in Section 5, not a separate € figure.
A15: 3 — EXCEPTIONS & TAIL RISK
A16: Weekly exceptions (routine) | B16: =Assumptions!B28*Assumptions!B5 -> 30 | C16: =Assumptions!B29*Assumptions!B5 -> 50 | D16: Cost already reflected in Section 2 — not priced separately.
A17: Fatal incidents per year | B17: =Assumptions!B30*12 -> 60 | D17: <5/month × 12
A18: Worst-case exposure ceiling (annual) | B18: =B17*Assumptions!B31 -> 3000000 | D18: Hard cap if every incident hit the max — not a typical outcome.
A19: Illustrative expected exposure (annual) | B19: =B17*Assumptions!B31*Assumptions!B32 -> 600000 | D19: Uses the illustrative severity assumption on the Assumptions tab — replace once real claims data exists.
A21: 4 — MARGIN LEVERAGE & REVENUE GROWTH
A22: Profit from €1 of new revenue (at current margin) | B22: =Assumptions!B35 -> 0.05 | C22: =Assumptions!B36 -> 0.06
A23: Leverage: 1 cost-€ saved ≈ X revenue-€ generated | B23: =1/Assumptions!B36 -> 16.666667 | C23: =1/Assumptions!B35 -> 20 | D23: At a 5–6% margin, cutting cost is worth 16–20x the equivalent revenue growth in profit terms.
A24: Revenue growth target, in € | B24: =IF(Assumptions!B37="","enter revenue",Assumptions!B37*Assumptions!B40) -> 15964000 | C24: =IF(Assumptions!B37="","enter revenue",Assumptions!B37*Assumptions!B41) -> 21285333 | D24: Blank until Assumptions!Current annual revenue is filled in.
A25: Profit impact of that revenue growth | B25: =IF(Assumptions!B37="","enter revenue",Assumptions!B37*Assumptions!B40*Assumptions!B35) -> 798200 | C25: =IF(Assumptions!B37="","enter revenue",Assumptions!B37*Assumptions!B41*Assumptions!B36) -> 1277120 | D25: Revenue growth × margin — shows how little of that growth reaches the bottom line vs. cost savings.
A27: 5 — SCALING +25–50% VOLUME WITHOUT ADDING HEADCOUNT
A28: Current throughput | B28: =Assumptions!B5/Assumptions!B7 -> 8.3333333 | D28: Loads per employee per week, today
A29: Employees needed at target volume (old way) | B29: =Assumptions!B38/B28 -> 150 | C29: =Assumptions!B39/B28 -> 180 | D29: If throughput per person never improved
A30: Additional hires avoided | B30: =B29-Assumptions!B7 -> 30 | C30: =C29-Assumptions!B7 -> 60
A31: Avoided hiring cost (annual) | B31: =B30*Assumptions!B19 -> 1174500 | C31: =C30*Assumptions!B19 -> 2349000 | D31: An alternate lens on the same efficiency gain as Section 2 — do not add to it.
A32: Processing-cost savings AT scaled volume | B32: =(Assumptions!B10-Assumptions!B11)*Assumptions!B38*Assumptions!B6 -> 2600000 | C32: =(Assumptions!B10-Assumptions!B11)*Assumptions!B39*Assumptions!B6 -> 3120000 | D32: Run-rate once volume reaches the target band — the headline scaling number.
A34: 6 — RETURN ON THE CORE BUILD INVESTMENT ONLY (simplified — see Systems Cost & Net ROI tab for the full picture)
A35: Investment (Core build only, with 15% contingency — excl. technical setup & running costs) | B35: =Assumptions!B46 -> 46460 | D35: From the proposal's cost estimate — Core build only
A36: Payback period, at current volume (Core build only) | B36: =Assumptions!B46/B12*365 -> 8.1528365
A37: Year-1 net benefit, at current volume (Core build only) | B37: =B12-Assumptions!B46 -> 2033540
A38: Run-rate net benefit once scaled to target volume (Core build only) | B38: =B32-Assumptions!B46 -> 2553540 | C38: =C32-Assumptions!B46 -> 3073540 | D38: Same one-time investment; savings grow as volume grows onto the same platform.
A39: ⚠ This section excludes the technical setup & running costs (VPS, WhatsApp, GPS, Sheets) — a modest deduction now that the SAP-upgrade contingency and optional-AI-layer costs from the prior SAP BTP proposal no longer apply. See the 'Systems Cost & Net ROI' tab for the realistic, all-in comparison.

Sheet Systems Cost & Net ROI
A1: Systems Cost & Net ROI — The Realistic, All-In Picture
A2: Section 6 of the Calculations tab only nets the Core build fee against savings. This tab adds what that leaves out — technical setup & running costs (VPS, WhatsApp, GPS, Sheets) — so the opportunity vs. investment comparison reflects the real cost of the system, not just SilverTrust's build fee. The SAP technical-upgrade contingency and optional Generative-AI-layer costs from the prior SAP BTP proposal (v3) no longer apply: n8n reads SAP by email, and AI processing is built into the Core, not a removable add-on.
A4: A — ONE-TIME INVESTMENT
B5: Low | C5: High
A6: Core build (SilverTrust fee, with 15% contingency) | B6: =Assumptions!B46 -> 46460 | C6: =Assumptions!B46 -> 46460 | D6: Same figure both columns — the build fee is fixed, not a range
A7: + Technical setup costs (VPS, WhatsApp/Meta, GPS hardware, AI model design) | B7: =Assumptions!B52 -> 3250 | C7: =Assumptions!B53 -> 4500 | D7: See 'n8n Running Costs' tab for the per-component build
A8: TOTAL ONE-TIME INVESTMENT, YEAR 1 | B8: =B6+B7 -> 49710 | C8: =C6+C7 -> 50960
A10: B — RECURRING CLIENT-SIDE COSTS (annual, ongoing)
A11: VPS + WhatsApp templates + GPS tracking + Sheets (monthly × 12) | B11: =Assumptions!B54*12 -> 5544 | C11: =Assumptions!B55*12 -> 8400 | D11: Recurring cost only — excludes the one-time setup counted in Section A
A12: Forward deployed engineer, loaded annual cost (client FTE, from handover) | B12: =Assumptions!B64 -> 87750 | C12: =Assumptions!B65 -> 94500 | D12: SilverTrust does not provide ongoing n8n flow maintenance — see Out of Scope. Full FTE modeled; a fractional allocation could reduce this. (https://www.salaryexpert.com/salary/job/engineer/spain/barcelona)
A13: TOTAL RECURRING COST, PER YEAR (from Year 1 handover) | B13: =B11+B12 -> 93294 | C13: =C11+C12 -> 102900
A15: C — YEAR 1 NET OPPORTUNITY (excl. AI — already in the Core build above)
A16: Gross annual savings at current volume | B16: =Calculations!B12 -> 2080000 | C16: =Calculations!B12 -> 2080000 | D16: From Calculations, Section 2 — same both columns
A17: Less: Core build (with contingency) | B17: =-B6 -> -46460 | C17: =-C6 -> -46460
A18: Less: Year 1 technical setup cost | B18: =-B7 -> -3250 | C18: =-C7 -> -4500
A19: Less: Year 1 recurring running costs | B19: =-B11 -> -5544 | C19: =-C11 -> -8400
A20: Less: Year 1 maintenance engineer (client FTE) | B20: =-B12 -> -87750 | C20: =-C12 -> -94500
A21: NET YEAR 1 BENEFIT | B21: =SUM(B16:B20) -> 1936996 | C21: =SUM(C16:C20) -> 1926140 | D21: Now includes the client-side maintenance FTE — see note below
A22: Payback period | B22: =(B8+B13)/B16*365 -> 25.094452 | C22: =(C8+C13)/C16*365 -> 26.999471 | D22: Time to recover the full Year 1 investment (build + setup + running costs + maintenance FTE) from gross savings
A24: D — 3-YEAR NET OPPORTUNITY (conservative — savings held flat, no assumed volume growth)
A25: Cumulative gross savings, 3 years | B25: =B16*3 -> 6240000 | C25: =C16*3 -> 6240000 | D25: Current-volume headline savings × 3 — conservative, ignores the scaling upside
A26: Less: one-time investment (build + setup) | B26: =-B8 -> -49710 | C26: =-C8 -> -50960
A27: Less: 3 years of recurring running costs (incl. maintenance FTE) | B27: =-B13*3 -> -279882 | C27: =-C13*3 -> -308700
A28: NET 3-YEAR BENEFIT | B28: =SUM(B25:B27) -> 5910408 | C28: =SUM(C25:C27) -> 5880340
A30: E — BENCHMARK: SAVING VS. SAP BTP ROUTE (on equivalent functionality)
A31: SAP BTP Integration Suite licence alone (annual) | B31: ='n8n Running Costs'!C27 -> 20000 | C31: ='n8n Running Costs'!C28 -> 40000 | D31: For equivalent functionality, before any implementation cost — see 'n8n Running Costs' tab, Comparison section
A32: Saving vs. SAP BTP route (annual) | B32: ='n8n Running Costs'!C29 -> 11000 | C32: ='n8n Running Costs'!C30 -> 30000 | D32: n8n self-hosted has no execution limits, no per-seat fees, no vendor lock-in. Source: n8n Cost Breakdown doc.
A33: See 'SilverTrust Cost Detail' tab, Section G, for the full boutique vs. mid-market vs. Big 4 build-cost & timeline comparison.
A35: All figures marked "SilverTrust illustrative" or "pending vendor quote" on the Assumptions / n8n Running Costs tabs (VPS, WhatsApp templates, GPS tracking, maintenance engineer salary) are NOT vendor- or hire-confirmed — replace with a real quote or offer letter as they come in, per the proposal's Sources & Caveats slide. This tab exists so the opportunity-vs-investment story never overstates the net benefit by quietly ignoring what SilverTrust's fee doesn't cover.
